Workbook

Sheet README
A1: READ ME FIRST
A3: IMPORTANT
B4: This workbook includes a "Tesla hits all targets" scenario. It assumes Tesla delivers every milestone in Musk's 2025 CEO award, its Master Plan ambitions,
B5: robotaxi and Optimus at massive scale, AND a merger with SpaceX (SPCX). That is extremely optimistic: Tesla has missed or dropped many past targets.
B6: Nothing here is a forecast or financial advice. Share prices can fall as well as rise; check with a regulated adviser before acting.
A8: HOW TO USE
A9: 1. | B9: Inputs sheet → cell B4: pick a scenario from the drop-down (Tesla hits all targets / Base / Conservative).
A10: 2. | B10: Yellow cells anywhere are editable: TSLA/SPCX price, FX rate, merger Yes/No, merger year, exchange-ratio method, premium, and every scenario assumption.
A11: 3. | B11: Dashboard: headline numbers, CEO-award milestone checker, merger maths, a what-if price calculator and charts.
A12: 4. | B12: Holdings: your master list of shares and buy prices (live value, profit, £). Choose whether to include Caroline on the Inputs sheet.
A13: 5. | B13: Projection: the full 2026–2046 model for the active scenario. Proj_Targets / Proj_Base / Proj_Conservative run all three side by side.
A14: 6. | B14: Your original sheets are kept (with fixes) at the end. Changelog lists every fix; Sources lists every reference.
A16: ON IPHONE | B16: Open in the Microsoft Excel app (not Files preview) so drop-downs and recalculation work. Interactive web version:
B17: https://colin-3d-models.netlify.app/tesla-model/

Sheet Dashboard
A1: TESLA (+SPACEX) POSITION DASHBOARD
A2: =CONCATENATE("Scenario: ",Inputs!B4," | Merger: ",Inputs!$B$19,IF(Inputs!$B$19="Yes"," in "&Inputs!$B$20,"")," | Prices as of ",Inputs!$B$10) -> Scenario: Tesla hits all targets | Merger: Yes in 2027 | Prices as of 8 Oct 2026
A3: Change the scenario and every assumption on the Inputs sheet (yellow cells). Very optimistic what-if model – not a forecast, not advice.
A5: TSLA price now | C5: My shares | E5: My position now (£) | G5: Profit so far (£, today's FX) | I5: Gain % | K5: $1 TSLA move = £
A6: =Inputs!$B$9 -> 375 | C6: =Holdings!D15 -> 368.48 | E6: =Holdings!D15*Inputs!$B$9/Inputs!$B$14 -> 104452.34 | G6: =(Holdings!D15*Inputs!$B$9-Holdings!D17)/Inputs!$B$14 -> 35378.551 | I6: =IFERROR(Holdings!D15*Inputs!$B$9/Holdings!D17-1,0) -> 0.5121849 | K6: =Holdings!D18 -> 278.53957
A8: Headline results – active scenario | K8: CEO award milestone checker (Tesla standalone, active scenario)
A9: Year | B9: Value per TSLA share ($) | C9: x today | D9: My position ($) | E9: My position (£) | F9: £ in today's money | G9: Tesla revenue ($bn) | H9: Tesla EBITDA ($bn) | I9: Tesla mkt cap ($bn) | K9: Milestone | L9: Target | M9: First year reached | N9: By award deadline?
A10: 2027 | B10: =INDEX(Projection!$AL$8:$AL$28,MATCH($A10,Projection!$A$8:$A$28,0)) -> 500.29627 | C10: =INDEX(Projection!$AP$8:$AP$28,MATCH($A10,Projection!$A$8:$A$28,0)) -> 1.3341234 | D10: =INDEX(Projection!$AM$8:$AM$28,MATCH($A10,Projection!$A$8:$A$28,0)) -> 184349.17 | E10: =INDEX(Projection!$AN$8:$AN$28,MATCH($A10,Projection!$A$8:$A$28,0)) -> 139352.31 | F10: =INDEX(Projection!$AO$8:$AO$28,MATCH($A10,Projection!$A$8:$A$28,0)) -> 135953.47 | G10: =INDEX(Projection!$V$8:$V$28,MATCH($A10,Projection!$A$8:$A$28,0)) -> 134.74473 | H10: =INDEX(Projection!$W$8:$W$28,MATCH($A10,Projection!$A$8:$A$28,0)) -> 17.25624 | I10: =INDEX(Projection!$AA$8:$AA$28,MATCH($A10,Projection!$A$8:$A$28,0)) -> 1368.5759 | K10: Market cap $8.5tn | L10: =Inputs!$B$56 -> 8500 | M10: =IF(COUNTIF(Projection!$AA$8:$AA$28,">="&L10)=0,"Not by 2046",_xlfn.MINIFS(Projection!$A$8:$A$28,Projection!$AA$8:$AA$28,">="&L10)) -> 2032 | N10: =IF(ISNUMBER(M10),IF(M10<=Inputs!$B$62,"YES","LATE"),"NO") -> YES
A11: 2030 | B11: =INDEX(Projection!$AL$8:$AL$28,MATCH($A11,Projection!$A$8:$A$28,0)) -> 2700.8483 | C11: =INDEX(Projection!$AP$8:$AP$28,MATCH($A11,Projection!$A$8:$A$28,0)) -> 7.202262 | D11: =INDEX(Projection!$AM$8:$AM$28,MATCH($A11,Projection!$A$8:$A$28,0)) -> 995208.57 | E11: =INDEX(Projection!$AN$8:$AN$28,MATCH($A11,Projection!$A$8:$A$28,0)) -> 752293.12 | F11: =INDEX(Projection!$AO$8:$AO$28,MATCH($A11,Projection!$A$8:$A$28,0)) -> 681540.44 | G11: =INDEX(Projection!$V$8:$V$28,MATCH($A11,Projection!$A$8:$A$28,0)) -> 330.72309 | H11: =INDEX(Projection!$W$8:$W$28,MATCH($A11,Projection!$A$8:$A$28,0)) -> 80.04108 | I11: =INDEX(Projection!$AA$8:$AA$28,MATCH($A11,Projection!$A$8:$A$28,0)) -> 4644.7445 | K11: 20m cumulative vehicles | L11: =Inputs!$B$57 -> 20 | M11: =IF(COUNTIF(Projection!$E$8:$E$28,">="&L11)=0,"Not by 2046",_xlfn.MINIFS(Projection!$A$8:$A$28,Projection!$E$8:$E$28,">="&L11)) -> 2030 | N11: =IF(ISNUMBER(M11),IF(M11<=Inputs!$B$62,"YES","LATE"),"NO") -> YES
A12: 2036 | B12: =INDEX(Projection!$AL$8:$AL$28,MATCH($A12,Projection!$A$8:$A$28,0)) -> 3858.6711 | C12: =INDEX(Projection!$AP$8:$AP$28,MATCH($A12,Projection!$A$8:$A$28,0)) -> 10.289789 | D12: =INDEX(Projection!$AM$8:$AM$28,MATCH($A12,Projection!$A$8:$A$28,0)) -> 1421843.1 | E12: =INDEX(Projection!$AN$8:$AN$28,MATCH($A12,Projection!$A$8:$A$28,0)) -> 1074792.6 | F12: =INDEX(Projection!$AO$8:$AO$28,MATCH($A12,Projection!$A$8:$A$28,0)) -> 839626.25 | G12: =INDEX(Projection!$V$8:$V$28,MATCH($A12,Projection!$A$8:$A$28,0)) -> 1432.6612 | H12: =INDEX(Projection!$W$8:$W$28,MATCH($A12,Projection!$A$8:$A$28,0)) -> 563.21018 | I12: =INDEX(Projection!$AA$8:$AA$28,MATCH($A12,Projection!$A$8:$A$28,0)) -> 15189.419 | K12: 10m paid FSD subs | L12: =Inputs!$B$58 -> 10 | M12: =IF(COUNTIF(Projection!$H$8:$H$28,">="&L12)=0,"Not by 2046",_xlfn.MINIFS(Projection!$A$8:$A$28,Projection!$H$8:$H$28,">="&L12)) -> 2031 | N12: =IF(ISNUMBER(M12),IF(M12<=Inputs!$B$62,"YES","LATE"),"NO") -> YES
A13: 2041 | B13: =INDEX(Projection!$AL$8:$AL$28,MATCH($A13,Projection!$A$8:$A$28,0)) -> 3451.7244 | C13: =INDEX(Projection!$AP$8:$AP$28,MATCH($A13,Projection!$A$8:$A$28,0)) -> 9.2045985 | D13: =INDEX(Projection!$AM$8:$AM$28,MATCH($A13,Projection!$A$8:$A$28,0)) -> 1271891.4 | E13: =INDEX(Projection!$AN$8:$AN$28,MATCH($A13,Projection!$A$8:$A$28,0)) -> 961441.84 | F13: =INDEX(Projection!$AO$8:$AO$28,MATCH($A13,Projection!$A$8:$A$28,0)) -> 663842.48 | G13: =INDEX(Projection!$V$8:$V$28,MATCH($A13,Projection!$A$8:$A$28,0)) -> 2012.1148 | H13: =INDEX(Projection!$W$8:$W$28,MATCH($A13,Projection!$A$8:$A$28,0)) -> 804.21903 | I13: =INDEX(Projection!$AA$8:$AA$28,MATCH($A13,Projection!$A$8:$A$28,0)) -> 16367.431 | K13: 1m robotaxis operating | L13: =Inputs!$B$59 -> 1 | M13: =IF(COUNTIF(Projection!$J$8:$J$28,">="&L13)=0,"Not by 2046",_xlfn.MINIFS(Projection!$A$8:$A$28,Projection!$J$8:$J$28,">="&L13)) -> 2030 | N13: =IF(ISNUMBER(M13),IF(M13<=Inputs!$B$62,"YES","LATE"),"NO") -> YES
A14: 2046 | B14: =INDEX(Projection!$AL$8:$AL$28,MATCH($A14,Projection!$A$8:$A$28,0)) -> 3307.0295 | C14: =INDEX(Projection!$AP$8:$AP$28,MATCH($A14,Projection!$A$8:$A$28,0)) -> 8.8187453 | D14: =INDEX(Projection!$AM$8:$AM$28,MATCH($A14,Projection!$A$8:$A$28,0)) -> 1218574.2 | E14: =INDEX(Projection!$AN$8:$AN$28,MATCH($A14,Projection!$A$8:$A$28,0)) -> 921138.58 | F14: =INDEX(Projection!$AO$8:$AO$28,MATCH($A14,Projection!$A$8:$A$28,0)) -> 562144.11 | G14: =INDEX(Projection!$V$8:$V$28,MATCH($A14,Projection!$A$8:$A$28,0)) -> 2108.2435 | H14: =INDEX(Projection!$W$8:$W$28,MATCH($A14,Projection!$A$8:$A$28,0)) -> 838.47267 | I14: =INDEX(Projection!$AA$8:$AA$28,MATCH($A14,Projection!$A$8:$A$28,0)) -> 16847.876 | K14: 1m Optimus delivered | L14: =Inputs!$B$60 -> 1 | M14: =IF(COUNTIF(Projection!$O$8:$O$28,">="&L14)=0,"Not by 2046",_xlfn.MINIFS(Projection!$A$8:$A$28,Projection!$O$8:$O$28,">="&L14)) -> 2031 | N14: =IF(ISNUMBER(M14),IF(M14<=Inputs!$B$62,"YES","LATE"),"NO") -> YES
A15: (You can type any year 2026–2046 in the yellow year cells.) | K15: $400bn adj. EBITDA | L15: =Inputs!$B$61 -> 400 | M15: =IF(COUNTIF(Projection!$W$8:$W$28,">="&L15)=0,"Not by 2046",_xlfn.MINIFS(Projection!$A$8:$A$28,Projection!$W$8:$W$28,">="&L15)) -> 2035 | N15: =IF(ISNUMBER(M15),IF(M15<=Inputs!$B$62,"YES","LATE"),"NO") -> YES
K16: =CONCATENATE("Milestones met by ",Inputs!$B$62,": ",COUNTIF(N10:N15,"YES")," of 6") -> Milestones met by 2035: 6 of 6
A17: Scenario comparison – value per original TSLA share ($) and my position (£)
A18: Year | B18: Targets $/sh | C18: Base $/sh | D18: Conservative $/sh | E18: Targets £ | F18: Base £ | G18: Conservative £ | H18: Active $/sh | I18: Active £ | K18: Merger maths
A19: 2026 | B19: =Proj_Targets!AL8 -> 375 | C19: =Proj_Base!AL8 -> 375 | D19: =Proj_Conservative!AL8 -> 375 | E19: =Proj_Targets!AN8 -> 104452.34 | F19: =Proj_Base!AN8 -> 104452.34 | G19: =Proj_Conservative!AN8 -> 104452.34 | H19: =Projection!AL8 -> 375 | I19: =Projection!AN8 -> 104452.34 | K19: Exchange ratio (SPCX shares per TSLA share) | N19: =Projection!B4 -> 2.33543
A20: 2027 | B20: =Proj_Targets!AL9 -> 500.29627 | C20: =Proj_Base!AL9 -> 299.09812 | D20: =Proj_Conservative!AL9 -> 266.77224 | E20: =Proj_Targets!AN9 -> 139352.31 | F20: =Proj_Base!AN9 -> 83310.663 | G20: =Proj_Conservative!AN9 -> 74306.626 | H20: =Projection!AL9 -> 500.29627 | I20: =Projection!AN9 -> 139352.31 | K20: Tesla holders' share of combined company | N20: =Projection!B4*Inputs!$B$11/(Inputs!$B$13+Projection!B4*Inputs!$B$11) -> 0.40466506
A21: 2028 | B21: =Proj_Targets!AL10 -> 993.9081 | C21: =Proj_Base!AL10 -> 264.25939 | D21: =Proj_Conservative!AL10 -> 166.23784 | E21: =Proj_Targets!AN10 -> 276842.74 | F21: =Proj_Base!AN10 -> 73606.698 | G21: =Proj_Conservative!AN10 -> 46303.818 | H21: =Projection!AL10 -> 993.9081 | I21: =Projection!AN10 -> 276842.74 | K21: Ratio implied by today's prices | N21: =Inputs!$B$9/Inputs!$B$12 -> 2.33543
A22: 2029 | B22: =Proj_Targets!AL11 -> 2003.3866 | C22: =Proj_Base!AL11 -> 283.9854 | D22: =Proj_Conservative!AL11 -> 74.547024 | E22: =Proj_Targets!AN11 -> 558022.44 | F22: =Proj_Base!AN11 -> 79101.173 | G22: =Proj_Conservative!AN11 -> 20764.296 | H22: =Projection!AL11 -> 2003.3866 | I22: =Projection!AN11 -> 558022.44 | K22: Ratio for a 50/50 split today | N22: =Inputs!$B$13/Inputs!$B$11 -> 3.4358367
A23: 2030 | B23: =Proj_Targets!AL12 -> 2700.8483 | C23: =Proj_Base!AL12 -> 365.4939 | D23: =Proj_Conservative!AL12 -> 80.781574 | E23: =Proj_Targets!AN12 -> 752293.12 | F23: =Proj_Base!AN12 -> 101804.51 | G23: =Proj_Conservative!AN12 -> 22500.865 | H23: =Projection!AL12 -> 2700.8483 | I23: =Projection!AN12 -> 752293.12 | K23: SPCX shares you would receive | N23: =Projection!B4*Holdings!D15 -> 860.55926
A24: 2031 | B24: =Proj_Targets!AL13 -> 3348.2639 | C24: =Proj_Base!AL13 -> 455.21372 | D24: =Proj_Conservative!AL13 -> 87.851082 | E24: =Proj_Targets!AN13 -> 932623.99 | F24: =Proj_Base!AN13 -> 126795.04 | G24: =Proj_Conservative!AN13 -> 24470.003 | H24: =Projection!AL13 -> 3348.2639 | I24: =Projection!AN13 -> 932623.99
A25: 2032 | B25: =Proj_Targets!AL14 -> 3684.1126 | C25: =Proj_Base!AL14 -> 529.78527 | D25: =Proj_Conservative!AL14 -> 96.989383 | E25: =Proj_Targets!AN14 -> 1026171.1 | F25: =Proj_Base!AN14 -> 147566.16 | G25: =Proj_Conservative!AN14 -> 27015.381 | H25: =Projection!AL14 -> 3684.1126 | I25: =Projection!AN14 -> 1026171.1 | K25: Quick what-if: if TSLA (or value per share) were…
A26: 2033 | B26: =Proj_Targets!AL15 -> 3875.0189 | C26: =Proj_Base!AL15 -> 592.90567 | D26: =Proj_Conservative!AL15 -> 106.01355 | E26: =Proj_Targets!AN15 -> 1079346.1 | F26: =Proj_Base!AN15 -> 165147.69 | G26: =Proj_Conservative!AN15 -> 29528.969 | H26: =Projection!AL15 -> 3875.0189 | I26: =Projection!AN15 -> 1079346.1 | K26: Price per share ($) | N26: 1000
A27: 2034 | B27: =Proj_Targets!AL16 -> 3975.1368 | C27: =Proj_Base!AL16 -> 641.32218 | D27: =Proj_Conservative!AL16 -> 114.01172 | E27: =Proj_Targets!AN16 -> 1107232.9 | F27: =Proj_Base!AN16 -> 178633.61 | G27: =Proj_Conservative!AN16 -> 31756.775 | H27: =Projection!AL16 -> 3975.1368 | I27: =Projection!AN16 -> 1107232.9 | K27: …my position would be (£) | N27: =N26*Holdings!D15/Inputs!$B$14 -> 278539.57
A28: 2035 | B28: =Proj_Targets!AL17 -> 3966.6592 | C28: =Proj_Base!AL17 -> 670.21675 | D28: =Proj_Conservative!AL17 -> 120.1136 | E28: =Proj_Targets!AN17 -> 1104871.5 | F28: =Proj_Base!AN17 -> 186681.89 | G28: =Proj_Conservative!AN17 -> 33456.39 | H28: =Projection!AL17 -> 3966.6592 | I28: =Projection!AN17 -> 1104871.5
A29: 2036 | B29: =Proj_Targets!AL18 -> 3858.6711 | C29: =Proj_Base!AL18 -> 679.04124 | D29: =Proj_Conservative!AL18 -> 123.67737 | E29: =Proj_Targets!AN18 -> 1074792.6 | F29: =Proj_Base!AN18 -> 189139.86 | G29: =Proj_Conservative!AN18 -> 34449.043 | H29: =Projection!AL18 -> 3858.6711 | I29: =Projection!AN18 -> 1074792.6
A30: 2037 | B30: =Proj_Targets!AL19 -> 3678.2298 | C30: =Proj_Base!AL19 -> 669.25963 | D30: =Proj_Conservative!AL19 -> 124.40622 | E30: =Proj_Targets!AN19 -> 1024532.5 | F30: =Proj_Base!AN19 -> 186415.29 | G30: =Proj_Conservative!AN19 -> 34652.055 | H30: =Projection!AL19 -> 3678.2298 | I30: =Projection!AN19 -> 1024532.5
A31: 2038 | B31: =Proj_Targets!AL20 -> 3434.6528 | C31: =Proj_Base!AL20 -> 643.34955 | D31: =Proj_Conservative!AL20 -> 122.34696 | E31: =Proj_Targets!AN20 -> 956686.73 | F31: =Proj_Base!AN20 -> 179198.31 | G31: =Proj_Conservative!AN20 -> 34078.47 | H31: =Projection!AL20 -> 3434.6528 | I31: =Projection!AN20 -> 956686.73
A32: 2039 | B32: =Proj_Targets!AL21 -> 3462.7063 | C32: =Proj_Base!AL21 -> 664.3639 | D32: =Proj_Conservative!AL21 -> 127.25538 | E32: =Proj_Targets!AN21 -> 964500.74 | F32: =Proj_Base!AN21 -> 185051.64 | G32: =Proj_Conservative!AN21 -> 35445.66 | H32: =Projection!AL21 -> 3462.7063 | I32: =Projection!AN21 -> 964500.74
A33: 2040 | B33: =Proj_Targets!AL22 -> 3465.7194 | C33: =Proj_Base!AL22 -> 677.70619 | D33: =Proj_Conservative!AL22 -> 130.72784 | E33: =Proj_Targets!AN22 -> 965340.01 | F33: =Proj_Base!AN22 -> 188767.99 | G33: =Proj_Conservative!AN22 -> 36412.878 | H33: =Projection!AL22 -> 3465.7194 | I33: =Projection!AN22 -> 965340.01
A34: 2041 | B34: =Proj_Targets!AL23 -> 3451.7244 | C34: =Proj_Base!AL23 -> 684.88418 | D34: =Proj_Conservative!AL23 -> 132.83215 | E34: =Proj_Targets!AN23 -> 961441.84 | F34: =Proj_Base!AN23 -> 190767.35 | G34: =Proj_Conservative!AN23 -> 36999.01 | H34: =Projection!AL23 -> 3451.7244 | I34: =Projection!AN23 -> 961441.84
A35: 2042 | B35: =Proj_Targets!AL24 -> 3429.992 | C35: =Proj_Base!AL24 -> 687.22044 | D35: =Proj_Conservative!AL24 -> 133.7759 | E35: =Proj_Targets!AN24 -> 955388.49 | F35: =Proj_Base!AN24 -> 191418.09 | G35: =Proj_Conservative!AN24 -> 37261.882 | H35: =Projection!AL24 -> 3429.992 | I35: =Projection!AN24 -> 955388.49
A36: 2043 | B36: =Proj_Targets!AL25 -> 3403.0899 | C36: =Proj_Base!AL25 -> 685.89998 | D36: =Proj_Conservative!AL25 -> 133.77675 | E36: =Proj_Targets!AN25 -> 947895.2 | F36: =Proj_Base!AN25 -> 191050.29 | G36: =Proj_Conservative!AN25 -> 37262.119 | H36: =Projection!AL25 -> 3403.0899 | I36: =Projection!AN25 -> 947895.2
A37: 2044 | B37: =Proj_Targets!AL26 -> 3373.3273 | C37: =Proj_Base!AL26 -> 681.75498 | D37: =Proj_Conservative!AL26 -> 133.04102 | E37: =Proj_Targets!AN26 -> 939605.15 | F37: =Proj_Base!AN26 -> 189895.74 | G37: =Proj_Conservative!AN26 -> 37057.188 | H37: =Projection!AL26 -> 3373.3273 | I37: =Projection!AN26 -> 939605.15
A38: 2045 | B38: =Proj_Targets!AL27 -> 3340.9446 | C38: =Proj_Base!AL27 -> 675.56542 | D38: =Proj_Conservative!AL27 -> 131.76308 | E38: =Proj_Targets!AN27 -> 930585.28 | F38: =Proj_Base!AN27 -> 188171.7 | G38: =Proj_Conservative!AN27 -> 36701.232 | H38: =Projection!AL27 -> 3340.9446 | I38: =Projection!AN27 -> 930585.28
A39: 2046 | B39: =Proj_Targets!AL28 -> 3307.0295 | C39: =Proj_Base!AL28 -> 667.98267 | D39: =Proj_Conservative!AL28 -> 130.14241 | E39: =Proj_Targets!AN28 -> 921138.58 | F39: =Proj_Base!AN28 -> 186059.61 | G39: =Proj_Conservative!AN28 -> 36249.812 | H39: =Projection!AL28 -> 3307.0295 | I39: =Projection!AN28 -> 921138.58

Sheet Inputs
A1: CONTROL PANEL – change the yellow cells; everything else recalculates
A2: WARNING: the "Tesla hits all targets" scenario assumes Tesla AND SpaceX deliver every stated ambition on time. Tesla has missed many past targets (e.g. it dropped its 20m-cars-a-year goal). This is a what-if model, not a forecast and not financial advice.
A4: Scenario (drop-down) | B4: Tesla hits all targets
A5: Scenario number (auto) | B5: =MATCH(B4,$C$64:$E$64,0) -> 1
A7: Global input | B7: Value | F7: Unit | G7: Source / note
A8: Market data (update these when you check prices)
A9: TSLA share price | B9: 375 | F9: $ | G9: Close 8 Oct 2026 [S1]
A10: Price date | B10: 8 Oct 2026 | G10: Type the date you update the price
A11: TSLA shares outstanding | B11: 3.9495474 | F11: bn | G11: 3,949,547,394 at 16 Jul 2026 incl. unearned award shares [S4]
A12: SPCX (SpaceX) share price | B12: 160.57 | F12: $ | G12: Close 8 Oct 2026 [S2]
A13: SPCX shares outstanding | B13: 13.57 | F13: bn | G13: CNBC 13.57bn [S2]
A14: GBP/USD exchange rate ($ per £1) | B14: 1.3229 | F14: $/£ | G14: Close 8 Oct 2026 [S3]. Original file used 1.3375 (0.74766 £/$)
A15: Your holdings & personal settings
A16: Include Caroline's holdings in projections? | B16: No | F16: Yes/No | G16: Colin only by default
A17: UK inflation for "today's money" values | B17: 0.025 | F17: %/yr | G17: Assumption
A18: SpaceX merger
A19: Tesla–SpaceX merger happens? | B19: Yes | F19: Yes/No | G19: No deal announced as of 5 Oct 2026; Polymarket 62.5% by end-2027 [S21]
A20: Merger completion year | B20: 2027 | F20: year | G20: Assumption (prediction markets centre on 2027) [S21]
A21: Exchange-ratio method | B21: Today's market prices | G21: Market ratio ≈ TSLA/SPCX price; FinanceFeeds 2.385 at 18 Sep prices [S22]
A22: Premium paid to Tesla holders | B22: 0 | F22: % | G22: 0% = at market. Morningstar argues holders deserve 50–68% of combined co [S23]; ~3.34 ratio = 50/50 [S22]
A23: Manual exchange ratio (SPCX shares per TSLA share) | B23: 3.34 | F23: x | G23: Only used if method = Manual
A24: Model mechanics
A25: Years for share price to converge to model value | B25: 3 | F25: years | G25: Assumption – smooths the jump from today's market price
A26: Year multiple reaches its mature level | B26: 2038 | F26: year | G26: Assumption
A27: Years for margins to reach mature level | B27: 6 | F27: years | G27: Assumption
A28: Tesla net cash & investments | B28: 37.7 | F28: $bn | G28: Cash $43.5bn – debt $9.3bn + SpaceX stake + bitcoin (30 Jun 2026) [S24]
A29: 2026 starting points (Tesla)
A30: 2026E vehicle deliveries | B30: 1.81 | F30: m | G30: H1 0.84m [S6] + Q3 0.487m [S5] + Q4 assumed ~0.49m
A31: Cumulative deliveries at end-2025 | B31: 8.9 | F31: m | G31: Tesla Q4 2025 deck [S7]
A32: Vehicle ASP 2026 | B32: 41.5 | F32: $k | G32: H1 2026 ≈ $42.3k incl. FSD [S24]
A33: Automotive EBITDA margin 2026 | B33: 0.12 | F33: % | G33: Assumption [S24]
A34: Paid FSD subscribers 2026E | B34: 1.6 | F34: m | G34: 1.48m at Q2 2026 [S6]
A35: Robotaxi fleet end-2026E | B35: 0.002 | F35: m | G35: ~546 Texas vehicles by Sep 2026 + other metros (Assumption) [S24]
A36: Robotaxi fare 2026 | B36: 1.5 | F36: $/mile | G36: Assumption (Tesla does not publish)
A37: Robotaxi fare decline per year | B37: 0.05 | F37: % | G37: Assumption
A38: Robotaxi EBITDA margin 2026 | B38: 0.2 | F38: % | G38: Assumption
A39: Optimus units delivered 2026E | B39: 0.005 | F39: m | G39: Assumption – "several hundred a week" reported, unconfirmed [S24]
A40: Optimus price 2026 | B40: 50 | F40: $k | G40: Assumption
A41: Optimus price decline per year | B41: 0.08 | F41: % | G41: Assumption
... A54: SpaceX EBITDA margin 2026 | B54: 0.35 | F54: % | G54: H1 2026 ≈ 37% [S17]
...

Sheet Holdings
A1: MY TESLA HOLDINGS – master list (share counts & buy prices exactly as in your sheets)
A2: Edit shares / average buy prices in yellow. Prices & FX come from Inputs. Optional column M: type your real £ cost if you know it (FX at purchase differs from today).
A4: Owner | B4: Platform | C4: Account type | D4: Shares | E4: Avg buy $ | F4: Cost $ | G4: Price $ | H4: Value $ | I4: Profit $ | J4: Gain % | K4: Value £ | L4: Cost £ (at today's FX) | M4: Actual £ cost (optional) | N4: Profit £ | O4: Taken from sheet
A5: Colin | B5: Money Box | C5: ISA | D5: 276.44 | E5: 237.11 | F5: =D5*E5 -> 65546.688 | G5: =Inputs!$B$9 -> 375 | H5: =D5*G5 -> 103665 | I5: =H5-F5 -> 38118.312 | J5: =IFERROR(I5/F5,0) -> 0.58154443 | K5: =H5/Inputs!$B$14 -> 78361.932 | L5: =F5/Inputs!$B$14 -> 49547.727 | N5: =K5-IF(M5="",L5,M5) -> 28814.205 | O5: 'Colin'!C3
A6: Colin | B6: Trading 212 | C6: Non-ISA | D6: 0 | E6: 336.41 | F6: =D6*E6 -> 0 | G6: =Inputs!$B$9 -> 375 | H6: =D6*G6 -> 0 | I6: =H6-F6 -> 0 | J6: =IFERROR(I6/F6,0) -> 0 | K6: =H6/Inputs!$B$14 -> 0 | L6: =F6/Inputs!$B$14 -> 0 | N6: =K6-IF(M6="",L6,M6) -> 0 | O6: 'Colin'!C4
A7: Colin | B7: Trading 212 | C7: ISA | D7: 92.04 | E7: 280.65 | F7: =D7*E7 -> 25831.026 | G7: =Inputs!$B$9 -> 375 | H7: =D7*G7 -> 34515 | I7: =H7-F7 -> 8683.974 | J7: =IFERROR(I7/F7,0) -> 0.33618386 | K7: =H7/Inputs!$B$14 -> 26090.407 | L7: =F7/Inputs!$B$14 -> 19526.061 | N7: =K7-IF(M7="",L7,M7) -> 6564.3465 | O7: 'Colin'!C5
A8: Caroline | B8: Money Box | C8: ISA | D8: 109.6 | E8: 349.29 | F8: =D8*E8 -> 38282.184 | G8: =Inputs!$B$9 -> 375 | H8: =D8*G8 -> 41100 | I8: =H8-F8 -> 2817.816 | J8: =IFERROR(I8/F8,0) -> 0.073606459 | K8: =H8/Inputs!$B$14 -> 31068.108 | L8: =F8/Inputs!$B$14 -> 28938.078 | N8: =K8-IF(M8="",L8,M8) -> 2130.0295 | O8: 'Colin & CAroline'!D7
A9: Caroline | B9: Trading 212 | C9: ? (Caroline sheet says 'Stocks') | D9: 6 | E9: 443 | F9: =D9*E9 -> 2658 | G9: =Inputs!$B$9 -> 375 | H9: =D9*G9 -> 2250 | I9: =H9-F9 -> -408 | J9: =IFERROR(I9/F9,0) -> -0.15349887 | K9: =H9/Inputs!$B$14 -> 1700.8088 | L9: =F9/Inputs!$B$14 -> 2009.2222 | N9: =K9-IF(M9="",L9,M9) -> -308.41333 | O9: 'Colin & CAroline'!D8
A11: Colin total | D11: =SUM(D5:D7) -> 368.48 | E11: =IFERROR(F11/D11,0) -> 247.98555 | F11: =SUM(F5:F7) -> 91377.714 | G11: =Inputs!$B$9 -> 375 | H11: =SUM(H5:H7) -> 138180 | I11: =SUM(I5:I7) -> 46802.286 | J11: =IFERROR(I11/F11,0) -> 0.5121849 | K11: =SUM(K5:K7) -> 104452.34 | L11: =SUM(L5:L7) -> 69073.788 | N11: =SUM(N5:N7) -> 35378.551
A12: Caroline total | D12: =SUM(D8:D9) -> 115.6 | E12: =IFERROR(F12/D12,0) -> 354.15384 | F12: =SUM(F8:F9) -> 40940.184 | G12: =Inputs!$B$9 -> 375 | H12: =SUM(H8:H9) -> 43350 | I12: =SUM(I8:I9) -> 2409.816 | J12: =IFERROR(I12/F12,0) -> 0.058861875 | K12: =SUM(K8:K9) -> 32768.917 | L12: =SUM(L8:L9) -> 30947.301 | N12: =SUM(N8:N9) -> 1821.6161
A13: Household total | D13: =D11+D12 -> 484.08 | E13: =IFERROR(F13/D13,0) -> 273.33891 | F13: =F11+F12 -> 132317.9 | G13: =Inputs!$B$9 -> 375 | H13: =H11+H12 -> 181530 | I13: =I11+I12 -> 49212.102 | J13: =IFERROR(I13/F13,0) -> 0.37192324 | K13: =K11+K12 -> 137221.26 | L13: =L11+L12 -> 100021.09 | N13: =N11+N12 -> 37200.168
A15: Shares used in projections | D15: =D11+IF(Inputs!$B$16="Yes",D12,0) -> 368.48 | E15: =IF(Inputs!$B$16="Yes","Colin + Caroline","Colin only") -> Colin only
A16: Weighted average buy price used ($) | D16: =IF(Inputs!$B$16="Yes",E13,E11) -> 247.98555
A17: Cost basis used ($) | D17: =IF(Inputs!$B$16="Yes",F13,F11) -> 91377.714
A18: What does a $1 move in TSLA mean for me? (£) | D18: =D15/Inputs!$B$14 -> 278.53957
A20: Data check notes:
A21: • Colin's share counts differ between sheets: 'Colin' (276.44 / 0 / 92.04 = 368.48), 'Colin & CAroline' (275.56 / 55 / 33.12 = 363.68), 'InvestAnswers' (266.48 / 65.11 / 14.062 = 345.652). The 'Colin' sheet looks newest (non-ISA moved to ISA) and is used here – please confirm.
A22: • Trading 212 ISA average buy price is still $280.65 although shares rose from 33.12 to 92.04 – check the platform for the current average.
A23: • Caroline: 'Colin & CAroline' sheet (109.6 / 6 shares) used; 'Caroline' sheet has 107.95 / 6.04. Account type for her Trading 212 holding is '?' in one sheet and 'Stocks' in the other.
A24: • £ cost is shown at today's FX. Your true £ cost depends on the exchange rate on each purchase date – type it in column M if you know it (the platform app shows it).

Sheet Projection
A1: 20-YEAR PROJECTION – ACTIVE SCENARIO (2026–2046)
A2: Scenario # | B2: =Inputs!$B$5 -> 1 | C2: =INDEX(Inputs!$C$64:$E$64,$B$2) -> Tesla hits all targets
A3: All figures are formulas driven by the Inputs sheet. $bn unless stated. 2047 row is a helper (forward EBITDA for the 2046 valuation).
A4: Exchange ratio used (SPCX per TSLA) | B4: =IF(Inputs!$B$21="Manual",Inputs!$B$23,IF(Inputs!$B$21="Projected prices in merger year",INDEX($AB$8:$AB$28,MATCH($B$5,$A$8:$A$28,0))/INDEX($AG$8:$AG$28,MATCH($B$5,$A$8:$A$28,0)),Inputs!$B$9/Inputs!$B$12)*(1+Inputs!$B$22)) -> 2.33543
A5: Merger year | B5: =Inputs!$B$20 -> 2027
A7: Year | B7: Years from 2026 | C7: Margin ramp | D7: Car deliveries (m) | E7: Cumulative deliveries incl. robotaxis (m) | F7: Car ASP ($k) | G7: Auto revenue ($bn) | H7: Paid FSD subs (m) | I7: FSD revenue ($bn) | J7: Robotaxi fleet (m) | K7: Avg fleet (m) | L7: Fare ($/mile) | M7: Robotaxi revenue ($bn) | N7: Optimus units (m) | O7: Cumulative Optimus (m) | P7: Optimus price ($k) | Q7: Optimus revenue ($bn) | R7: Storage deployed (GWh) | S7: Energy $/kWh | T7: Energy revenue ($bn) | U7: Services revenue ($bn) | V7: TOTAL REVENUE ($bn) | W7: Adj. EBITDA ($bn) | X7: Net income ($bn) | Y7: EV/EBITDA multiple (x) | Z7: TSLA shares (bn) | AA7: Tesla equity value ($bn) | AB7: Tesla standalone $/share | AC7: SpaceX revenue ($bn) | AD7: SpaceX EBITDA ($bn) | AE7: SPCX shares (bn) | AF7: SpaceX equity value ($bn) | AG7: SPCX $/share | AH7: Merged? (1=yes) | AI7: Combined equity ($bn) | AJ7: Combined shares (bn) | AK7: Tesla holders' ownership | AL7: VALUE PER ORIGINAL TSLA SHARE ($) | AM7: My position ($) | AN7: My position (£) | AO7: My position (£, today's money) | AP7: x today's price
A8: 2026 | B8: =A8-2026 -> 0 | C8: =MIN(1,B8/Inputs!$B$27) -> 0 | D8: =Inputs!$B$30+($B$33-Inputs!$B$30)*((1/(1+EXP(-$B$35*($A8-$B$34))))-(1/(1+EXP(-$B$35*(2026-$B$34)))))/(1-(1/(1+EXP(-$B$35*(2026-$B$34))))) -> 1.81 | E8: =Inputs!$B$31+D8+J8 -> 10.712 | F8: =MAX($B$37,Inputs!$B$32*(1+$B$36)^B8) -> 41.5 | G8: =D8*F8 -> 75.115 | H8: =Inputs!$B$34+($B$39-Inputs!$B$34)*((1/(1+EXP(-$B$41*($A8-$B$40))))-(1/(1+EXP(-$B$41*(2026-$B$40)))))/(1-(1/(1+EXP(-$B$41*(2026-$B$40))))) -> 1.6 | I8: =H8*$B$42*12/1000 -> 1.92 | J8: =Inputs!$B$35+($B$44-Inputs!$B$35)*((1/(1+EXP(-$B$46*($A8-$B$45))))-(1/(1+EXP(-$B$46*(2026-$B$45)))))/(1-(1/(1+EXP(-$B$46*(2026-$B$45))))) -> 0.002 | K8: =J8/2 -> 0.001 | L8: =MAX($B$48,Inputs!$B$36*(1-Inputs!$B$37)^B8) -> 1.5 | M8: =K8*$B$47*L8 -> 0.09 | N8: =Inputs!$B$39+($B$50-Inputs!$B$39)*((1/(1+EXP(-$B$52*($A8-$B$51))))-(1/(1+EXP(-$B$52*(2026-$B$51)))))/(1-(1/(1+EXP(-$B$52*(2026-$B$51))))) -> 0.005 | O8: =N8 -> 0.005 | P8: =MAX($B$53,Inputs!$B$40*(1-Inputs!$B$41)^B8) -> 50 | Q8: =N8*P8 -> 0.25 | R8: =Inputs!$B$43+($B$55-Inputs!$B$43)*((1/(1+EXP(-$B$57*($A8-$B$56))))-(1/(1+EXP(-$B$57*(2026-$B$56)))))/(1-(1/(1+EXP(-$B$57*(2026-$B$56))))) -> 52 | S8: =MAX($B$58,Inputs!$B$44*(1-Inputs!$B$45)^B8) -> 245 | T8: =R8*S8/1000 -> 12.74 | U8: =Inputs!$B$47 -> 17.5 | V8: =G8+I8+M8+Q8+T8+U8 -> 107.615 | W8: =G8*(Inputs!$B$33+($B$38-Inputs!$B$33)*C8)+I8*$B$43+M8*(Inputs!$B$38+($B$49-Inputs!$B$38)*C8)+Q8*(Inputs!$B$42+($B$54-Inputs!$B$42)*C8)+T8*(Inputs!$B$46+($B$59-Inputs!$B$46)*C8)+U8*$B$61-V8*Inputs!$B$49 -> 13.3385 | X8: =(W8-V8*(Inputs!$B$50+Inputs!$B$51))*(1-Inputs!$B$52) -> 2.03583 | Y8: =$B$62+($B$63-$B$62)*MIN(1,MAX(0,(A8-2027)/(Inputs!$B$26-2027))) -> 40 | Z8: =Inputs!$B$11*(1+$B$64)^B8 -> 3.9495474 | AA8: =MIN(1,B8/Inputs!$B$25)*(W9*Y8+Inputs!$B$28)+(1-MIN(1,B8/Inputs!$B$25))*Inputs!$B$9*Inputs!$B$11 -> 1481.0803 | AB8: =AA8/Z8 -> 375 | AC8: =Inputs!$B$53+($B$65-Inputs!$B$53)*((1/(1+EXP(-$B$67*($A8-$B$66))))-(1/(1+EXP(-$B$67*(2026-$B$66)))))/(1-(1/(1+EXP(-$B$67*(2026-$B$66))))) -> 32 | AD8: =AC8*(Inputs!$B$54+($B$68-Inputs!$B$54)*C8) -> 11.2 | AE8: =Inputs!$B$13*(1+$B$69)^B8 -> 13.57 | AF8: =MIN(1,B8/Inputs!$B$25)*(AD9*Y8)+(1-MIN(1,B8/Inputs!$B$25))*Inputs!$B$12*Inputs!$B$13 -> 2178.9349 | AG8: =AF8/AE8 -> 160.57 | AH8: =IF(AND(Inputs!$B$19="Yes",A8>=$B$5),1,0) -> 0 | AI8: =(AA8+AF8)*(1+IF(AH8=1,$B$70*MIN(1,(A8-$B$5+1)/3),0)) -> 3660.0152 | AJ8: =AE8+Z8*$B$4 -> 22.793892 | AK8: =IF(AH8=1,Z8*$B$4/AJ8,1) -> 1 | AL8: =IF(AH8=1,$B$4*AI8/AJ8,AB8) -> 375 | AM8: =AL8*Holdings!$D$15 -> 138180 | AN8: =AM8/Inputs!$B$14 -> 104452.34 | AO8: =AN8/(1+Inputs!$B$17)^B8 -> 104452.34 | AP8: =AL8/Inputs!$B$9 -> 1
A9: 2027 | B9: =A9-2026 -> 1 | C9: =MIN(1,B9/Inputs!$B$27) -> 0.16666667 | D9: =Inputs!$B$30+($B$33-Inputs!$B$30)*((1/(1+EXP(-$B$35*($A9-$B$34))))-(1/(1+EXP(-$B$35*(2026-$B$34)))))/(1-(1/(1+EXP(-$B$35*(2026-$B$34))))) -> 2.0448721 | E9: =E8-J8+D9+J9 -> 12.941384 | F9: =MAX($B$37,Inputs!$B$32*(1+$B$36)^B9) -> 40.67 | G9: =D9*F9 -> 83.164947 | H9: =Inputs!$B$34+($B$39-Inputs!$B$34)*((1/(1+EXP(-$B$41*($A9-$B$40))))-(1/(1+EXP(-$B$41*(2026-$B$40)))))/(1-(1/(1+EXP(-$B$41*(2026-$B$40))))) -> 2.3206916 | I9: =H9*$B$42*12/1000 -> 2.7848299 | J9: =Inputs!$B$35+($B$44-Inputs!$B$35)*((1/(1+EXP(-$B$46*($A9-$B$45))))-(1/(1+EXP(-$B$46*(2026-$B$45)))))/(1-(1/(1+EXP(-$B$46*(2026-$B$45))))) -> 0.18651236 | K9: =(J9+J8)/2 -> 0.094256179 | L9: =MAX($B$48,Inputs!$B$36*(1-Inputs!$B$37)^B9) -> 1.425 | M9: =K9*$B$47*L9 -> 8.0589033 | N9: =Inputs!$B$39+($B$50-Inputs!$B$39)*((1/(1+EXP(-$B$52*($A9-$B$51))))-(1/(1+EXP(-$B$52*(2026-$B$51)))))/(1-(1/(1+EXP(-$B$52*(2026-$B$51))))) -> 0.056854686 | O9: =O8+N9 -> 0.061854686 | P9: =MAX($B$53,Inputs!$B$40*(1-Inputs!$B$41)^B9) -> 46 | Q9: =N9*P9 -> 2.6153155 | R9: =Inputs!$B$43+($B$55-Inputs!$B$43)*((1/(1+EXP(-$B$57*($A9-$B$56))))-(1/(1+EXP(-$B$57*(2026-$B$56)))))/(1-(1/(1+EXP(-$B$57*(2026-$B$56))))) -> 76.512485 | S9: =MAX($B$58,Inputs!$B$44*(1-Inputs!$B$45)^B9) -> 235.2 | T9: =R9*S9/1000 -> 17.995737 | U9: =U8*(1+$B$60*Inputs!$B$48^(B9-1)) -> 20.125 | V9: =G9+I9+M9+Q9+T9+U9 -> 134.74473 | W9: =G9*(Inputs!$B$33+($B$38-Inputs!$B$33)*C9)+I9*$B$43+M9*(Inputs!$B$38+($B$49-Inputs!$B$38)*C9)+Q9*(Inputs!$B$42+($B$54-Inputs!$B$42)*C9)+T9*(Inputs!$B$46+($B$59-Inputs!$B$46)*C9)+U9*$B$61-V9*Inputs!$B$49 -> 17.25624 | X9: =(W9-V9*(Inputs!$B$50+Inputs!$B$51))*(1-Inputs!$B$52) -> 2.9875956 | Y9: =$B$62+($B$63-$B$62)*MIN(1,MAX(0,(A9-2027)/(Inputs!$B$26-2027))) -> 40 | Z9: =Inputs!$B$11*(1+$B$64)^B9 -> 3.9692951 | AA9: =MIN(1,B9/Inputs!$B$25)*(W10*Y9+Inputs!$B$28)+(1-MIN(1,B9/Inputs!$B$25))*Inputs!$B$9*Inputs!$B$11 -> 1368.5759 | AB9: =AA9/Z9 -> 344.79067 | AC9: =Inputs!$B$53+($B$65-Inputs!$B$53)*((1/(1+EXP(-$B$67*($A9-$B$66))))-(1/(1+EXP(-$B$67*(2026-$B$66)))))/(1-(1/(1+EXP(-$B$67*(2026-$B$66))))) -> 170.75536 | AD9: =AC9*(Inputs!$B$54+($B$68-Inputs!$B$54)*C9) -> 62.610299 | AE9: =Inputs!$B$13*(1+$B$69)^B9 -> 13.77355 | AF9: =MIN(1,B9/Inputs!$B$25)*(AD10*Y9)+(1-MIN(1,B9/Inputs!$B$25))*Inputs!$B$12*Inputs!$B$13 -> 3408.5815 | AG9: =AF9/AE9 -> 247.47299 | AH9: =IF(AND(Inputs!$B$19="Yes",A9>=$B$5),1,0) -> 1 | AI9: =(AA9+AF9)*(1+IF(AH9=1,$B$70*MIN(1,(A9-$B$5+1)/3),0)) -> 4936.396 | AJ9: =AE9+Z9*$B$4 -> 23.043561 | AK9: =IF(AH9=1,Z9*$B$4/AJ9,1) -> 0.40228205 | AL9: =IF(AH9=1,$B$4*AI9/AJ9,AB9) -> 500.29627 | AM9: =AL9*Holdings!$D$15 -> 184349.17 | AN9: =AM9/Inputs!$B$14 -> 139352.31 | AO9: =AN9/(1+Inputs!$B$17)^B9 -> 135953.47 | AP9: =AL9/Inputs!$B$9 -> 1.3341234
A10: 2028 | B10: =A10-2026 -> 2 | C10: =MIN(1,B10/Inputs!$B$27) -> 0.33333333 | D10: =Inputs!$B$30+($B$33-Inputs!$B$30)*((1/(1+EXP(-$B$35*($A10-$B$34))))-(1/(1+EXP(-$B$35*(2026-$B$34)))))/(1-(1/(1+EXP(-$B$35*(2026-$B$34))))) -> 2.3841994 | E10: =E9-J9+D10+J10 -> 15.620673 | F10: =MAX($B$37,Inputs!$B$32*(1+$B$36)^B10) -> 39.8566 | G10: =D10*F10 -> 95.026083 | H10: =Inputs!$B$34+($B$39-Inputs!$B$34)*((1/(1+EXP(-$B$41*($A10-$B$40))))-(1/(1+EXP(-$B$41*(2026-$B$40)))))/(1-(1/(1+EXP(-$B$41*(2026-$B$40))))) -> 3.4087225 | I10: =H10*$B$42*12/1000 -> 4.090467 | J10: =Inputs!$B$35+($B$44-Inputs!$B$35)*((1/(1+EXP(-$B$46*($A10-$B$45))))-(1/(1+EXP(-$B$46*(2026-$B$45)))))/(1-(1/(1+EXP(-$B$46*(2026-$B$45))))) -> 0.48160195 | K10: =(J10+J9)/2 -> 0.33405716 | L10: =MAX($B$48,Inputs!$B$36*(1-Inputs!$B$37)^B10) -> 1.35375 | M10: =K10*$B$47*L10 -> 27.133793 | N10: =Inputs!$B$39+($B$50-Inputs!$B$39)*((1/(1+EXP(-$B$52*($A10-$B$51))))-(1/(1+EXP(-$B$52*(2026-$B$51)))))/(1-(1/(1+EXP(-$B$52*(2026-$B$51))))) -> 0.14137659 | O10: =O9+N10 -> 0.20323128 | P10: =MAX($B$53,Inputs!$B$40*(1-Inputs!$B$41)^B10) -> 42.32 | Q10: =N10*P10 -> 5.9830573 | R10: =Inputs!$B$43+($B$55-Inputs!$B$43)*((1/(1+EXP(-$B$57*($A10-$B$56))))-(1/(1+EXP(-$B$57*(2026-$B$56)))))/(1-(1/(1+EXP(-$B$57*(2026-$B$56))))) -> 109.90629 | S10: =MAX($B$58,Inputs!$B$44*(1-Inputs!$B$45)^B10) -> 225.792 | T10: =R10*S10/1000 -> 24.815961 | U10: =U9*(1+$B$60*Inputs!$B$48^(B10-1)) -> 22.932437 | V10: =G10+I10+M10+Q10+T10+U10 -> 179.9818 | W10: =G10*(Inputs!$B$33+($B$38-Inputs!$B$33)*C10)+I10*$B$43+M10*(Inputs!$B$38+($B$49-Inputs!$B$38)*C10)+Q10*(Inputs!$B$42+($B$54-Inputs!$B$42)*C10)+T10*(Inputs!$B$46+($B$59-Inputs!$B$46)*C10)+U10*$B$61-V10*Inputs!$B$49 -> 27.64668 | X10: =(W10-V10*(Inputs!$B$50+Inputs!$B$51))*(1-Inputs!$B$52) -> 7.6223152 | Y10: =$B$62+($B$63-$B$62)*MIN(1,MAX(0,(A10-2027)/(Inputs!$B$26-2027))) -> 38.181818 | Z10: =Inputs!$B$11*(1+$B$64)^B10 -> 3.9891416 | AA10: =MIN(1,B10/Inputs!$B$25)*(W11*Y10+Inputs!$B$28)+(1-MIN(1,B10/Inputs!$B$25))*Inputs!$B$9*Inputs!$B$11 -> 1713.7987 | AB10: =AA10/Z10 -> 429.61591 | AC10: =Inputs!$B$53+($B$65-Inputs!$B$53)*((1/(1+EXP(-$B$67*($A10-$B$66))))-(1/(1+EXP(-$B$67*(2026-$B$66)))))/(1-(1/(1+EXP(-$B$67*(2026-$B$66))))) -> 382.68749 | AD10: =AC10*(Inputs!$B$54+($B$68-Inputs!$B$54)*C10) -> 146.69687 | AE10: =Inputs!$B$13*(1+$B$69)^B10 -> 13.980153 | AF10: =MIN(1,B10/Inputs!$B$25)*(AD11*Y10)+(1-MIN(1,B10/Inputs!$B$25))*Inputs!$B$12*Inputs!$B$13 -> 7581.0343 | AG10: =AF10/AE10 -> 542.27119 | AH10: =IF(AND(Inputs!$B$19="Yes",A10>=$B$5),1,0) -> 1 | AI10: =(AA10+AF10)*(1+IF(AH10=1,$B$70*MIN(1,(A10-$B$5+1)/3),0)) -> 9914.4885 | AJ10: =AE10+Z10*$B$4 -> 23.296514 | AK10: =IF(AH10=1,Z10*$B$4/AJ10,1) -> 0.39990365 | AL10: =IF(AH10=1,$B$4*AI10/AJ10,AB10) -> 993.9081 | AM10: =AL10*Holdings!$D$15 -> 366235.26 | AN10: =AM10/Inputs!$B$14 -> 276842.74 | AO10: =AN10/(1+Inputs!$B$17)^B10 -> 263502.9 | AP10: =AL10/Inputs!$B$9 -> 2.6504216
A11: 2029 | B11: =A11-2026 -> 3 | C11: =MIN(1,B11/Inputs!$B$27) -> 0.5 | D11: =Inputs!$B$30+($B$33-Inputs!$B$30)*((1/(1+EXP(-$B$35*($A11-$B$34))))-(1/(1+EXP(-$B$35*(2026-$B$34)))))/(1-(1/(1+EXP(-$B$35*(2026-$B$34))))) -> 2.8672312 | E11: =E10-J10+D11+J11 -> 18.951096 | F11: =MAX($B$37,Inputs!$B$32*(1+$B$36)^B11) -> 39.059468 | G11: =D11*F11 -> 111.99253 | H11: =Inputs!$B$34+($B$39-Inputs!$B$34)*((1/(1+EXP(-$B$41*($A11-$B$40))))-(1/(1+EXP(-$B$41*(2026-$B$40)))))/(1-(1/(1+EXP(-$B$41*(2026-$B$40))))) -> 5.0185426 | I11: =H11*$B$42*12/1000 -> 6.0222511 | J11: =Inputs!$B$35+($B$44-Inputs!$B$35)*((1/(1+EXP(-$B$46*($A11-$B$45))))-(1/(1+EXP(-$B$46*(2026-$B$45)))))/(1-(1/(1+EXP(-$B$46*(2026-$B$45))))) -> 0.94479305 | K11: =(J11+J10)/2 -> 0.7131975 | L11: =MAX($B$48,Inputs!$B$36*(1-Inputs!$B$37)^B11) -> 1.2860625 | M11: =K11*$B$47*L11 -> 55.032994 | N11: =Inputs!$B$39+($B$50-Inputs!$B$39)*((1/(1+EXP(-$B$52*($A11-$B$51))))-(1/(1+EXP(-$B$52*(2026-$B$51)))))/(1-(1/(1+EXP(-$B$52*(2026-$B$51))))) -> 0.2781476 | O11: =O10+N11 -> 0.48137887 | P11: =MAX($B$53,Inputs!$B$40*(1-Inputs!$B$41)^B11) -> 38.9344 | Q11: =N11*P11 -> 10.82951 | R11: =Inputs!$B$43+($B$55-Inputs!$B$43)*((1/(1+EXP(-$B$57*($A11-$B$56))))-(1/(1+EXP(-$B$57*(2026-$B$56)))))/(1-(1/(1+EXP(-$B$57*(2026-$B$56))))) -> 154.69176 | S11: =MAX($B$58,Inputs!$B$44*(1-Inputs!$B$45)^B11) -> 216.76032 | T11: =R11*S11/1000 -> 33.531036 | U11: =U10*(1+$B$60*Inputs!$B$48^(B11-1)) -> 25.907577 | V11: =G11+I11+M11+Q11+T11+U11 -> 243.31589 | W11: =G11*(Inputs!$B$33+($B$38-Inputs!$B$33)*C11)+I11*$B$43+M11*(Inputs!$B$38+($B$49-Inputs!$B$38)*C11)+Q11*(Inputs!$B$42+($B$54-Inputs!$B$42)*C11)+T11*(Inputs!$B$46+($B$59-Inputs!$B$46)*C11)+U11*$B$61-V11*Inputs!$B$49 -> 46.945326 | X11: =(W11-V11*(Inputs!$B$50+Inputs!$B$51))*(1-Inputs!$B$52) -> 17.864852 | Y11: =$B$62+($B$63-$B$62)*MIN(1,MAX(0,(A11-2027)/(Inputs!$B$26-2027))) -> 36.363636 | Z11: =Inputs!$B$11*(1+$B$64)^B11 -> 4.0090873 | AA11: =MIN(1,B11/Inputs!$B$25)*(W12*Y11+Inputs!$B$28)+(1-MIN(1,B11/Inputs!$B$25))*Inputs!$B$9*Inputs!$B$11 -> 2948.2847 | AB11: =AA11/Z11 -> 735.40048 | AC11: =Inputs!$B$53+($B$65-Inputs!$B$53)*((1/(1+EXP(-$B$67*($A11-$B$66))))-(1/(1+EXP(-$B$67*(2026-$B$66)))))/(1-(1/(1+EXP(-$B$67*(2026-$B$66))))) -> 673.23169 | AD11: =AC11*(Inputs!$B$54+($B$68-Inputs!$B$54)*C11) -> 269.29268 | AE11: =Inputs!$B$13*(1+$B$69)^B11 -> 14.189856 | AF11: =MIN(1,B11/Inputs!$B$25)*(AD12*Y11)+(1-MIN(1,B11/Inputs!$B$25))*Inputs!$B$12*Inputs!$B$13 -> 15419.117 | AG11: =AF11/AE11 -> 1086.6296 | AH11: =IF(AND(Inputs!$B$19="Yes",A11>=$B$5),1,0) -> 1 | AI11: =(AA11+AF11)*(1+IF(AH11=1,$B$70*MIN(1,(A11-$B$5+1)/3),0)) -> 20204.142 | AJ11: =AE11+Z11*$B$4 -> 23.552798 | AK11: =IF(AH11=1,Z11*$B$4/AJ11,1) -> 0.39752995 | AL11: =IF(AH11=1,$B$4*AI11/AJ11,AB11) -> 2003.3866 | AM11: =AL11*Holdings!$D$15 -> 738207.89 | AN11: =AM11/Inputs!$B$14 -> 558022.44 | AO11: =AN11/(1+Inputs!$B$17)^B11 -> 518179.31 | AP11: =AL11/Inputs!$B$9 -> 5.3423642
A12: 2030 | B12: =A12-2026 -> 4 | C12: =MIN(1,B12/Inputs!$B$27) -> 0.66666667 | D12: =Inputs!$B$30+($B$33-Inputs!$B$30)*((1/(1+EXP(-$B$35*($A12-$B$34))))-(1/(1+EXP(-$B$35*(2026-$B$34)))))/(1-(1/(1+EXP(-$B$35*(2026-$B$34))))) -> 3.5405287 | E12: =E11-J11+D12+J12 -> 23.197754 | F12: =MAX($B$37,Inputs!$B$32*(1+$B$36)^B12) -> 38.278279 | G12: =D12*F12 -> 135.52534 | H12: =Inputs!$B$34+($B$39-Inputs!$B$34)*((1/(1+EXP(-$B$41*($A12-$B$40))))-(1/(1+EXP(-$B$41*(2026-$B$40)))))/(1-(1/(1+EXP(-$B$41*(2026-$B$40))))) -> 7.3307169 | I12: =H12*$B$42*12/1000 -> 8.7968603 | J12: =Inputs!$B$35+($B$44-Inputs!$B$35)*((1/(1+EXP(-$B$46*($A12-$B$45))))-(1/(1+EXP(-$B$46*(2026-$B$45)))))/(1-(1/(1+EXP(-$B$46*(2026-$B$45))))) -> 1.6509228 | K12: =(J12+J11)/2 -> 1.2978579 | L12: =MAX($B$48,Inputs!$B$36*(1-Inputs!$B$37)^B12) -> 1.2217594 | M12: =K12*$B$47*L12 -> 95.140206 | N12: =Inputs!$B$39+($B$50-Inputs!$B$39)*((1/(1+EXP(-$B$52*($A12-$B$51))))-(1/(1+EXP(-$B$52*(2026-$B$51)))))/(1-(1/(1+EXP(-$B$52*(2026-$B$51))))) -> 0.49688471 | O12: =O11+N12 -> 0.97826359 | P12: =MAX($B$53,Inputs!$B$40*(1-Inputs!$B$41)^B12) -> 35.819648 | Q12: =N12*P12 -> 17.798236 | R12: =Inputs!$B$43+($B$55-Inputs!$B$43)*((1/(1+EXP(-$B$57*($A12-$B$56))))-(1/(1+EXP(-$B$57*(2026-$B$56)))))/(1-(1/(1+EXP(-$B$57*(2026-$B$56))))) -> 213.50877 | S12: =MAX($B$58,Inputs!$B$44*(1-Inputs!$B$45)^B12) -> 208.08991 | T12: =R12*S12/1000 -> 44.429021 | U12: =U11*(1+$B$60*Inputs!$B$48^(B12-1)) -> 29.033418 | V12: =G12+I12+M12+Q12+T12+U12 -> 330.72309 | W12: =G12*(Inputs!$B$33+($B$38-Inputs!$B$33)*C12)+I12*$B$43+M12*(Inputs!$B$38+($B$49-Inputs!$B$38)*C12)+Q12*(Inputs!$B$42+($B$54-Inputs!$B$42)*C12)+T12*(Inputs!$B$46+($B$59-Inputs!$B$46)*C12)+U12*$B$61-V12*Inputs!$B$49 -> 80.04108 | X12: =(W12-V12*(Inputs!$B$50+Inputs!$B$51))*(1-Inputs!$B$52) -> 37.105329 | Y12: =$B$62+($B$63-$B$62)*MIN(1,MAX(0,(A12-2027)/(Inputs!$B$26-2027))) -> 34.545455 | Z12: =Inputs!$B$11*(1+$B$64)^B12 -> 4.0291328 | AA12: =MIN(1,B12/Inputs!$B$25)*(W13*Y12+Inputs!$B$28)+(1-MIN(1,B12/Inputs!$B$25))*Inputs!$B$9*Inputs!$B$11 -> 4644.7445 | AB12: =AA12/Z12 -> 1152.7901 | AC12: =Inputs!$B$53+($B$65-Inputs!$B$53)*((1/(1+EXP(-$B$67*($A12-$B$66))))-(1/(1+EXP(-$B$67*(2026-$B$66)))))/(1-(1/(1+EXP(-$B$67*(2026-$B$66))))) -> 1017.6617 | AD12: =AC12*(Inputs!$B$54+($B$68-Inputs!$B$54)*C12) -> 424.02572 | AE12: =Inputs!$B$13*(1+$B$69)^B12 -> 14.402703 | AF12: =MIN(1,B12/Inputs!$B$25)*(AD13*Y12)+(1-MIN(1,B12/Inputs!$B$25))*Inputs!$B$12*Inputs!$B$13 -> 20390.101 | AG12: =AF12/AE12 -> 1415.7135 | AH12: =IF(AND(Inputs!$B$19="Yes",A12>=$B$5),1,0) -> 1 | AI12: =(AA12+AF12)*(1+IF(AH12=1,$B$70*MIN(1,(A12-$B$5+1)/3),0)) -> 27538.33 | AJ12: =AE12+Z12*$B$4 -> 23.812461 | AK12: =IF(AH12=1,Z12*$B$4/AJ12,1) -> 0.39516107 | AL12: =IF(AH12=1,$B$4*AI12/AJ12,AB12) -> 2700.8483 | AM12: =AL12*Holdings!$D$15 -> 995208.57 | AN12: =AM12/Inputs!$B$14 -> 752293.12 | AO12: =AN12/(1+Inputs!$B$17)^B12 -> 681540.44 | AP12: =AL12/Inputs!$B$9 -> 7.202262
A13: 2031 | B13: =A13-2026 -> 5 | C13: =MIN(1,B13/Inputs!$B$27) -> 0.83333333 | D13: =Inputs!$B$30+($B$33-Inputs!$B$30)*((1/(1+EXP(-$B$35*($A13-$B$34))))-(1/(1+EXP(-$B$35*(2026-$B$34)))))/(1-(1/(1+EXP(-$B$35*(2026-$B$34))))) -> 4.452057 | E13: =E12-J12+D13+J13 -> 28.679772 | F13: =MAX($B$37,Inputs!$B$32*(1+$B$36)^B13) -> 37.512713 | G13: =D13*F13 -> 167.00874 | H13: =Inputs!$B$34+($B$39-Inputs!$B$34)*((1/(1+EXP(-$B$41*($A13-$B$40))))-(1/(1+EXP(-$B$41*(2026-$B$40)))))/(1-(1/(1+EXP(-$B$41*(2026-$B$40))))) -> 10.513915 | I13: =H13*$B$42*12/1000 -> 12.616698 | J13: =Inputs!$B$35+($B$44-Inputs!$B$35)*((1/(1+EXP(-$B$46*($A13-$B$45))))-(1/(1+EXP(-$B$46*(2026-$B$45)))))/(1-(1/(1+EXP(-$B$46*(2026-$B$45))))) -> 2.6808831 | K13: =(J13+J12)/2 -> 2.165903 | L13: =MAX($B$48,Inputs!$B$36*(1-Inputs!$B$37)^B13) -> 1.1606714 | M13: =K13*$B$47*L13 -> 150.8341 | N13: =Inputs!$B$39+($B$50-Inputs!$B$39)*((1/(1+EXP(-$B$52*($A13-$B$51))))-(1/(1+EXP(-$B$52*(2026-$B$51)))))/(1-(1/(1+EXP(-$B$52*(2026-$B$51))))) -> 0.84022818 | O13: =O12+N13 -> 1.8184918 | P13: =MAX($B$53,Inputs!$B$40*(1-Inputs!$B$41)^B13) -> 32.954076 | Q13: =N13*P13 -> 27.688943 | R13: =Inputs!$B$43+($B$55-Inputs!$B$43)*((1/(1+EXP(-$B$57*($A13-$B$56))))-(1/(1+EXP(-$B$57*(2026-$B$56)))))/(1-(1/(1+EXP(-$B$57*(2026-$B$56))))) -> 288.66232 | S13: =MAX($B$58,Inputs!$B$44*(1-Inputs!$B$45)^B13) -> 199.76631 | T13: =R13*S13/1000 -> 57.665006 | U13: =U12*(1+$B$60*Inputs!$B$48^(B13-1)) -> 32.291195 | V13: =G13+I13+M13+Q13+T13+U13 -> 448.10468 | W13: =G13*(Inputs!$B$33+($B$38-Inputs!$B$33)*C13)+I13*$B$43+M13*(Inputs!$B$38+($B$49-Inputs!$B$38)*C13)+Q13*(Inputs!$B$42+($B$54-Inputs!$B$42)*C13)+T13*(Inputs!$B$46+($B$59-Inputs!$B$46)*C13)+U13*$B$61-V13*Inputs!$B$49 -> 133.36182 | X13: =(W13-V13*(Inputs!$B$50+Inputs!$B$51))*(1-Inputs!$B$52) -> 69.955565 | Y13: =$B$62+($B$63-$B$62)*MIN(1,MAX(0,(A13-2027)/(Inputs!$B$26-2027))) -> 32.727273 | Z13: =Inputs!$B$11*(1+$B$64)^B13 -> 4.0492784 | AA13: =MIN(1,B13/Inputs!$B$25)*(W14*Y13+Inputs!$B$28)+(1-MIN(1,B13/Inputs!$B$25))*Inputs!$B$9*Inputs!$B$11 -> 7039.9809 | AB13: =AA13/Z13 -> 1738.5766 | AC13: =Inputs!$B$53+($B$65-Inputs!$B$53)*((1/(1+EXP(-$B$67*($A13-$B$66))))-(1/(1+EXP(-$B$67*(2026-$B$66)))))/(1-(1/(1+EXP(-$B$67*(2026-$B$66))))) -> 1362.0918 | AD13: =AC13*(Inputs!$B$54+($B$68-Inputs!$B$54)*C13) -> 590.23977 | AE13: =Inputs!$B$13*(1+$B$69)^B13 -> 14.618744 | AF13: =MIN(1,B13/Inputs!$B$25)*(AD14*Y13)+(1-MIN(1,B13/Inputs!$B$25))*Inputs!$B$12*Inputs!$B$13 -> 24338.821 | AG13: =AF13/AE13 -> 1664.9051 | AH13: =IF(AND(Inputs!$B$19="Yes",A13>=$B$5),1,0) -> 1 | AI13: =(AA13+AF13)*(1+IF(AH13=1,$B$70*MIN(1,(A13-$B$5+1)/3),0)) -> 34516.682 | AJ13: =AE13+Z13*$B$4 -> 24.07555 | AK13: =IF(AH13=1,Z13*$B$4/AJ13,1) -> 0.3927971 | AL13: =IF(AH13=1,$B$4*AI13/AJ13,AB13) -> 3348.2639 | AM13: =AL13*Holdings!$D$15 -> 1233768.3 | AN13: =AM13/Inputs!$B$14 -> 932623.99 | AO13: =AN13/(1+Inputs!$B$17)^B13 -> 824303.71 | AP13: =AL13/Inputs!$B$9 -> 8.9287037
A14: 2032 | B14: =A14-2026 -> 6 | C14: =MIN(1,B14/Inputs!$B$27) -> 1 | D14: =Inputs!$B$30+($B$33-Inputs!$B$30)*((1/(1+EXP(-$B$35*($A14-$B$34))))-(1/(1+EXP(-$B$35*(2026-$B$34)))))/(1-(1/(1+EXP(-$B$35*(2026-$B$34))))) -> 5.6385631 | E14: =E13-J13+D14+J14 -> 35.727766 | F14: =MAX($B$37,Inputs!$B$32*(1+$B$36)^B14) -> 36.762459 | G14: =D14*F14 -> 207.28745 | H14: =Inputs!$B$34+($B$39-Inputs!$B$34)*((1/(1+EXP(-$B$41*($A14-$B$40))))-(1/(1+EXP(-$B$41*(2026-$B$40)))))/(1-(1/(1+EXP(-$B$41*(2026-$B$40))))) -> 14.649836 | I14: =H14*$B$42*12/1000 -> 17.579803 | J14: =Inputs!$B$35+($B$44-Inputs!$B$35)*((1/(1+EXP(-$B$46*($A14-$B$45))))-(1/(1+EXP(-$B$46*(2026-$B$45)))))/(1-(1/(1+EXP(-$B$46*(2026-$B$45))))) -> 4.0903148 | K14: =(J14+J13)/2 -> 3.3855989 | L14: =MAX($B$48,Inputs!$B$36*(1-Inputs!$B$37)^B14) -> 1.1026378 | M14: =K14*$B$47*L14 -> 223.98537 | N14: =Inputs!$B$39+($B$50-Inputs!$B$39)*((1/(1+EXP(-$B$52*($A14-$B$51))))-(1/(1+EXP(-$B$52*(2026-$B$51)))))/(1-(1/(1+EXP(-$B$52*(2026-$B$51))))) -> 1.3636516 | O14: =O13+N14 -> 3.1821433 | P14: =MAX($B$53,Inputs!$B$40*(1-Inputs!$B$41)^B14) -> 30.31775 | Q14: =N14*P14 -> 41.342847 | R14: =Inputs!$B$43+($B$55-Inputs!$B$43)*((1/(1+EXP(-$B$57*($A14-$B$56))))-(1/(1+EXP(-$B$57*(2026-$B$56)))))/(1-(1/(1+EXP(-$B$57*(2026-$B$56))))) -> 381.39295 | S14: =MAX($B$58,Inputs!$B$44*(1-Inputs!$B$45)^B14) -> 191.77566 | T14: =R14*S14/1000 -> 73.141885 | U14: =U13*(1+$B$60*Inputs!$B$48^(B14-1)) -> 35.660886 | V14: =G14+I14+M14+Q14+T14+U14 -> 598.99823 | W14: =G14*(Inputs!$B$33+($B$38-Inputs!$B$33)*C14)+I14*$B$43+M14*(Inputs!$B$38+($B$49-Inputs!$B$38)*C14)+Q14*(Inputs!$B$42+($B$54-Inputs!$B$42)*C14)+T14*(Inputs!$B$46+($B$59-Inputs!$B$46)*C14)+U14*$B$61-V14*Inputs!$B$49 -> 213.95858 | X14: =(W14-V14*(Inputs!$B$50+Inputs!$B$51))*(1-Inputs!$B$52) -> 121.70642 | Y14: =$B$62+($B$63-$B$62)*MIN(1,MAX(0,(A14-2027)/(Inputs!$B$26-2027))) -> 30.909091 | Z14: =Inputs!$B$11*(1+$B$64)^B14 -> 4.0695248 | AA14: =MIN(1,B14/Inputs!$B$25)*(W15*Y14+Inputs!$B$28)+(1-MIN(1,B14/Inputs!$B$25))*Inputs!$B$9*Inputs!$B$11 -> 8974.0911 | AB14: =AA14/Z14 -> 2205.1939 | AC14: =Inputs!$B$53+($B$65-Inputs!$B$53)*((1/(1+EXP(-$B$67*($A14-$B$66))))-(1/(1+EXP(-$B$67*(2026-$B$66)))))/(1-(1/(1+EXP(-$B$67*(2026-$B$66))))) -> 1652.636 | AD14: =AC14*(Inputs!$B$54+($B$68-Inputs!$B$54)*C14) -> 743.6862 | AE14: =Inputs!$B$13*(1+$B$69)^B14 -> 14.838025 | AF14: =MIN(1,B14/Inputs!$B$25)*(AD15*Y14)+(1-MIN(1,B14/Inputs!$B$25))*Inputs!$B$12*Inputs!$B$13 -> 25934.447 | AG14: =AF14/AE14 -> 1747.8369 | AH14: =IF(AND(Inputs!$B$19="Yes",A14>=$B$5),1,0) -> 1 | AI14: =(AA14+AF14)*(1+IF(AH14=1,$B$70*MIN(1,(A14-$B$5+1)/3),0)) -> 38399.392 | AJ14: =AE14+Z14*$B$4 -> 24.342116 | AK14: =IF(AH14=1,Z14*$B$4/AJ14,1) -> 0.39043815 | AL14: =IF(AH14=1,$B$4*AI14/AJ14,AB14) -> 3684.1126 | AM14: =AL14*Holdings!$D$15 -> 1357521.8 | AN14: =AM14/Inputs!$B$14 -> 1026171.1 | AO14: =AN14/(1+Inputs!$B$17)^B14 -> 884864.16 | AP14: =AL14/Inputs!$B$9 -> 9.8243002
A15: 2033 | B15: =A15-2026 -> 7 | C15: =MIN(1,B15/Inputs!$B$27) -> 1 | D15: =Inputs!$B$30+($B$33-Inputs!$B$30)*((1/(1+EXP(-$B$35*($A15-$B$34))))-(1/(1+EXP(-$B$35*(2026-$B$34)))))/(1-(1/(1+EXP(-$B$35*(2026-$B$34))))) -> 7.1064341 | E15: =E14-J14+D15+J15 -> 44.603392 | F15: =MAX($B$37,Inputs!$B$32*(1+$B$36)^B15) -> 36.02721 | G15: =D15*F15 -> 256.02499 | H15: =Inputs!$B$34+($B$39-Inputs!$B$34)*((1/(1+EXP(-$B$41*($A15-$B$40))))-(1/(1+EXP(-$B$41*(2026-$B$40)))))/(1-(1/(1+EXP(-$B$41*(2026-$B$40))))) -> 19.63751 | I15: =H15*$B$42*12/1000 -> 23.565012 | J15: =Inputs!$B$35+($B$44-Inputs!$B$35)*((1/(1+EXP(-$B$46*($A15-$B$45))))-(1/(1+EXP(-$B$46*(2026-$B$45)))))/(1-(1/(1+EXP(-$B$46*(2026-$B$45))))) -> 5.8595066 | K15: =(J15+J14)/2 -> 4.9749107 | L15: =MAX($B$48,Inputs!$B$36*(1-Inputs!$B$37)^B15) -> 1.0475059 | M15: =K15*$B$47*L15 -> 312.67491 | N15: =Inputs!$B$39+($B$50-Inputs!$B$39)*((1/(1+EXP(-$B$52*($A15-$B$51))))-(1/(1+EXP(-$B$52*(2026-$B$51)))))/(1-(1/(1+EXP(-$B$52*(2026-$B$51))))) -> 2.1271164 | O15: =O14+N15 -> 5.3092597 | P15: =MAX($B$53,Inputs!$B$40*(1-Inputs!$B$41)^B15) -> 27.89233 | Q15: =N15*P15 -> 59.330233 | R15: =Inputs!$B$43+($B$55-Inputs!$B$43)*((1/(1+EXP(-$B$57*($A15-$B$56))))-(1/(1+EXP(-$B$57*(2026-$B$56)))))/(1-(1/(1+EXP(-$B$57*(2026-$B$56))))) -> 491.00314 | S15: =MAX($B$58,Inputs!$B$44*(1-Inputs!$B$45)^B15) -> 184.10463 | T15: =R15*S15/1000 -> 90.395952 | U15: =U14*(1+$B$60*Inputs!$B$48^(B15-1)) -> 39.121722 | V15: =G15+I15+M15+Q15+T15+U15 -> 781.11282 | W15: =G15*(Inputs!$B$33+($B$38-Inputs!$B$33)*C15)+I15*$B$43+M15*(Inputs!$B$38+($B$49-Inputs!$B$38)*C15)+Q15*(Inputs!$B$42+($B$54-Inputs!$B$42)*C15)+T15*(Inputs!$B$46+($B$59-Inputs!$B$46)*C15)+U15*$B$61-V15*Inputs!$B$49 -> 289.11854 | X15: =(W15-V15*(Inputs!$B$50+Inputs!$B$51))*(1-Inputs!$B$52) -> 166.69573 | Y15: =$B$62+($B$63-$B$62)*MIN(1,MAX(0,(A15-2027)/(Inputs!$B$26-2027))) -> 29.090909 | Z15: =Inputs!$B$11*(1+$B$64)^B15 -> 4.0898724 | AA15: =MIN(1,B15/Inputs!$B$25)*(W16*Y15+Inputs!$B$28)+(1-MIN(1,B15/Inputs!$B$25))*Inputs!$B$9*Inputs!$B$11 -> 10899.535 | AB15: =AA15/Z15 -> 2665.0061 | AC15: =Inputs!$B$53+($B$65-Inputs!$B$53)*((1/(1+EXP(-$B$67*($A15-$B$66))))-(1/(1+EXP(-$B$67*(2026-$B$66)))))/(1-(1/(1+EXP(-$B$67*(2026-$B$66))))) -> 1864.5681 | AD15: =AC15*(Inputs!$B$54+($B$68-Inputs!$B$54)*C15) -> 839.05565 | AE15: =Inputs!$B$13*(1+$B$69)^B15 -> 15.060595 | AF15: =MIN(1,B15/Inputs!$B$25)*(AD16*Y15)+(1-MIN(1,B15/Inputs!$B$25))*Inputs!$B$12*Inputs!$B$13 -> 26225.326 | AG15: =AF15/AE15 -> 1741.3206 | AH15: =IF(AND(Inputs!$B$19="Yes",A15>=$B$5),1,0) -> 1 | AI15: =(AA15+AF15)*(1+IF(AH15=1,$B$70*MIN(1,(A15-$B$5+1)/3),0)) -> 40837.346 | AJ15: =AE15+Z15*$B$4 -> 24.612206 | AK15: =IF(AH15=1,Z15*$B$4/AJ15,1) -> 0.3880843 | AL15: =IF(AH15=1,$B$4*AI15/AJ15,AB15) -> 3875.0189 | AM15: =AL15*Holdings!$D$15 -> 1427867 | AN15: =AM15/Inputs!$B$14 -> 1079346.1 | AO15: =AN15/(1+Inputs!$B$17)^B15 -> 908016.36 | AP15: =AL15/Inputs!$B$9 -> 10.333384
A16: 2034 | B16: =A16-2026 -> 8 | C16: =MIN(1,B16/Inputs!$B$27) -> 1 | D16: =Inputs!$B$30+($B$33-Inputs!$B$30)*((1/(1+EXP(-$B$35*($A16-$B$34))))-(1/(1+EXP(-$B$35*(2026-$B$34)))))/(1-(1/(1+EXP(-$B$35*(2026-$B$34))))) -> 8.8123126 | E16: =E15-J15+D16+J16 -> 55.410692 | F16: =MAX($B$37,Inputs!$B$32*(1+$B$36)^B16) -> 35.306665 | G16: =D16*F16 -> 311.13337 | H16: =Inputs!$B$34+($B$39-Inputs!$B$34)*((1/(1+EXP(-$B$41*($A16-$B$40))))-(1/(1+EXP(-$B$41*(2026-$B$40)))))/(1-(1/(1+EXP(-$B$41*(2026-$B$40))))) -> 25.138766 | I16: =H16*$B$42*12/1000 -> 30.166519 | J16: =Inputs!$B$35+($B$44-Inputs!$B$35)*((1/(1+EXP(-$B$46*($A16-$B$45))))-(1/(1+EXP(-$B$46*(2026-$B$45)))))/(1-(1/(1+EXP(-$B$46*(2026-$B$45))))) -> 7.8544932 | K16: =(J16+J15)/2 -> 6.8569999 | L16: =MAX($B$48,Inputs!$B$36*(1-Inputs!$B$37)^B16) -> 1 | M16: =K16*$B$47*L16 -> 411.41999 | N16: =Inputs!$B$39+($B$50-Inputs!$B$39)*((1/(1+EXP(-$B$52*($A16-$B$51))))-(1/(1+EXP(-$B$52*(2026-$B$51)))))/(1-(1/(1+EXP(-$B$52*(2026-$B$51))))) -> 3.171867 | O16: =O15+N16 -> 8.4811267 | P16: =MAX($B$53,Inputs!$B$40*(1-Inputs!$B$41)^B16) -> 25.660944 | Q16: =N16*P16 -> 81.3931 | R16: =Inputs!$B$43+($B$55-Inputs!$B$43)*((1/(1+EXP(-$B$57*($A16-$B$56))))-(1/(1+EXP(-$B$57*(2026-$B$56)))))/(1-(1/(1+EXP(-$B$57*(2026-$B$56))))) -> 614.1782 | S16: =MAX($B$58,Inputs!$B$44*(1-Inputs!$B$45)^B16) -> 176.74045 | T16: =R16*S16/1000 -> 108.55013 | U16: =U15*(1+$B$60*Inputs!$B$48^(B16-1)) -> 42.652658 | V16: =G16+I16+M16+Q16+T16+U16 -> 985.31577 | W16: =G16*(Inputs!$B$33+($B$38-Inputs!$B$33)*C16)+I16*$B$43+M16*(Inputs!$B$38+($B$49-Inputs!$B$38)*C16)+Q16*(Inputs!$B$42+($B$54-Inputs!$B$42)*C16)+T16*(Inputs!$B$46+($B$59-Inputs!$B$46)*C16)+U16*$B$61-V16*Inputs!$B$49 -> 373.37557 | X16: =(W16-V16*(Inputs!$B$50+Inputs!$B$51))*(1-Inputs!$B$52) -> 217.12676 | Y16: =$B$62+($B$63-$B$62)*MIN(1,MAX(0,(A16-2027)/(Inputs!$B$26-2027))) -> 27.272727 | Z16: =Inputs!$B$11*(1+$B$64)^B16 -> 4.1103218 | AA16: =MIN(1,B16/Inputs!$B$25)*(W17*Y16+Inputs!$B$28)+(1-MIN(1,B16/Inputs!$B$25))*Inputs!$B$9*Inputs!$B$11 -> 12883.856 | AB16: =AA16/Z16 -> 3134.5128 | AC16: =Inputs!$B$53+($B$65-Inputs!$B$53)*((1/(1+EXP(-$B$67*($A16-$B$66))))-(1/(1+EXP(-$B$67*(2026-$B$66)))))/(1-(1/(1+EXP(-$B$67*(2026-$B$66))))) -> 2003.3235 | AD16: =AC16*(Inputs!$B$54+($B$68-Inputs!$B$54)*C16) -> 901.49556 | AE16: =Inputs!$B$13*(1+$B$69)^B16 -> 15.286504 | AF16: =MIN(1,B16/Inputs!$B$25)*(AD17*Y16)+(1-MIN(1,B16/Inputs!$B$25))*Inputs!$B$12*Inputs!$B$13 -> 25623.652 | AG16: =AF16/AE16 -> 1676.2271 | AH16: =IF(AND(Inputs!$B$19="Yes",A16>=$B$5),1,0) -> 1 | AI16: =(AA16+AF16)*(1+IF(AH16=1,$B$70*MIN(1,(A16-$B$5+1)/3),0)) -> 42358.259 | AJ16: =AE16+Z16*$B$4 -> 24.885873 | AK16: =IF(AH16=1,Z16*$B$4/AJ16,1) -> 0.38573567 | AL16: =IF(AH16=1,$B$4*AI16/AJ16,AB16) -> 3975.1368 | AM16: =AL16*Holdings!$D$15 -> 1464758.4 | AN16: =AM16/Inputs!$B$14 -> 1107232.9 | AO16: =AN16/(1+Inputs!$B$17)^B16 -> 908757.61 | AP16: =AL16/Inputs!$B$9 -> 10.600365
A17: 2035 | B17: =A17-2026 -> 9 | C17: =MIN(1,B17/Inputs!$B$27) -> 1 | D17: =Inputs!$B$30+($B$33-Inputs!$B$30)*((1/(1+EXP(-$B$35*($A17-$B$34))))-(1/(1+EXP(-$B$35*(2026-$B$34)))))/(1-(1/(1+EXP(-$B$35*(2026-$B$34))))) -> 10.656491 | E17: =E16-J16+D17+J17 -> 68.062169 | F17: =MAX($B$37,Inputs!$B$32*(1+$B$36)^B17) -> 34.600532 | G17: =D17*F17 -> 368.72025 | H17: =Inputs!$B$34+($B$39-Inputs!$B$34)*((1/(1+EXP(-$B$41*($A17-$B$40))))-(1/(1+EXP(-$B$41*(2026-$B$40)))))/(1-(1/(1+EXP(-$B$41*(2026-$B$40))))) -> 30.640022 | I17: =H17*$B$42*12/1000 -> 36.768026 | J17: =Inputs!$B$35+($B$44-Inputs!$B$35)*((1/(1+EXP(-$B$46*($A17-$B$45))))-(1/(1+EXP(-$B$46*(2026-$B$45)))))/(1-(1/(1+EXP(-$B$46*(2026-$B$45))))) -> 9.8494798 | K17: =(J17+J16)/2 -> 8.8519865 | L17: =MAX($B$48,Inputs!$B$36*(1-Inputs!$B$37)^B17) -> 1 | M17: =K17*$B$47*L17 -> 531.11919 | N17: =Inputs!$B$39+($B$50-Inputs!$B$39)*((1/(1+EXP(-$B$52*($A17-$B$51))))-(1/(1+EXP(-$B$52*(2026-$B$51)))))/(1-(1/(1+EXP(-$B$52*(2026-$B$51))))) -> 4.4832921 | O17: =O16+N17 -> 12.964419 | P17: =MAX($B$53,Inputs!$B$40*(1-Inputs!$B$41)^B17) -> 23.608068 | Q17: =N17*P17 -> 105.84187 | R17: =Inputs!$B$43+($B$55-Inputs!$B$43)*((1/(1+EXP(-$B$57*($A17-$B$56))))-(1/(1+EXP(-$B$57*(2026-$B$56)))))/(1-(1/(1+EXP(-$B$57*(2026-$B$56))))) -> 744.97506 | S17: =MAX($B$58,Inputs!$B$44*(1-Inputs!$B$45)^B17) -> 169.67083 | T17: =R17*S17/1000 -> 126.40054 | U17: =U16*(1+$B$60*Inputs!$B$48^(B17-1)) -> 46.232806 | V17: =G17+I17+M17+Q17+T17+U17 -> 1215.0827 | W17: =G17*(Inputs!$B$33+($B$38-Inputs!$B$33)*C17)+I17*$B$43+M17*(Inputs!$B$38+($B$49-Inputs!$B$38)*C17)+Q17*(Inputs!$B$42+($B$54-Inputs!$B$42)*C17)+T17*(Inputs!$B$46+($B$59-Inputs!$B$46)*C17)+U17*$B$61-V17*Inputs!$B$49 -> 471.02573 | X17: =(W17-V17*(Inputs!$B$50+Inputs!$B$51))*(1-Inputs!$B$52) -> 276.11879 | Y17: =$B$62+($B$63-$B$62)*MIN(1,MAX(0,(A17-2027)/(Inputs!$B$26-2027))) -> 25.454545 | Z17: =Inputs!$B$11*(1+$B$64)^B17 -> 4.1308734 | AA17: =MIN(1,B17/Inputs!$B$25)*(W18*Y17+Inputs!$B$28)+(1-MIN(1,B17/Inputs!$B$25))*Inputs!$B$9*Inputs!$B$11 -> 14373.959 | AB17: =AA17/Z17 -> 3479.6417 | AC17: =Inputs!$B$53+($B$65-Inputs!$B$53)*((1/(1+EXP(-$B$67*($A17-$B$66))))-(1/(1+EXP(-$B$67*(2026-$B$66)))))/(1-(1/(1+EXP(-$B$67*(2026-$B$66))))) -> 2087.8532 | AD17: =AC17*(Inputs!$B$54+($B$68-Inputs!$B$54)*C17) -> 939.53392 | AE17: =Inputs!$B$13*(1+$B$69)^B17 -> 15.515802 | AF17: =MIN(1,B17/Inputs!$B$25)*(AD18*Y17)+(1-MIN(1,B17/Inputs!$B$25))*Inputs!$B$12*Inputs!$B$13 -> 24479.586 | AG17: =AF17/AE17 -> 1577.7197 | AH17: =IF(AND(Inputs!$B$19="Yes",A17>=$B$5),1,0) -> 1 | AI17: =(AA17+AF17)*(1+IF(AH17=1,$B$70*MIN(1,(A17-$B$5+1)/3),0)) -> 42738.9 | AJ17: =AE17+Z17*$B$4 -> 25.163168 | AK17: =IF(AH17=1,Z17*$B$4/AJ17,1) -> 0.38339234 | AL17: =IF(AH17=1,$B$4*AI17/AJ17,AB17) -> 3966.6592 | AM17: =AL17*Holdings!$D$15 -> 1461634.6 | AN17: =AM17/Inputs!$B$14 -> 1104871.5 | AO17: =AN17/(1+Inputs!$B$17)^B17 -> 884701.98 | AP17: =AL17/Inputs!$B$9 -> 10.577758
A18: 2036 | B18: =A18-2026 -> 10 | C18: =MIN(1,B18/Inputs!$B$27) -> 1 | D18: =Inputs!$B$30+($B$33-Inputs!$B$30)*((1/(1+EXP(-$B$35*($A18-$B$34))))-(1/(1+EXP(-$B$35*(2026-$B$34)))))/(1-(1/(1+EXP(-$B$35*(2026-$B$34))))) -> 12.500669 | E18: =E17-J17+D18+J18 -> 82.33203 | F18: =MAX($B$37,Inputs!$B$32*(1+$B$36)^B18) -> 33.908521 | G18: =D18*F18 -> 423.8792 | H18: =Inputs!$B$34+($B$39-Inputs!$B$34)*((1/(1+EXP(-$B$41*($A18-$B$40))))-(1/(1+EXP(-$B$41*(2026-$B$40)))))/(1-(1/(1+EXP(-$B$41*(2026-$B$40))))) -> 35.627696 | I18: =H18*$B$42*12/1000 -> 42.753235 | J18: =Inputs!$B$35+($B$44-Inputs!$B$35)*((1/(1+EXP(-$B$46*($A18-$B$45))))-(1/(1+EXP(-$B$46*(2026-$B$45)))))/(1-(1/(1+EXP(-$B$46*(2026-$B$45))))) -> 11.618672 | K18: =(J18+J17)/2 -> 10.734076 | L18: =MAX($B$48,Inputs!$B$36*(1-Inputs!$B$37)^B18) -> 1 | M18: =K18*$B$47*L18 -> 644.04454 | N18: =Inputs!$B$39+($B$50-Inputs!$B$39)*((1/(1+EXP(-$B$52*($A18-$B$51))))-(1/(1+EXP(-$B$52*(2026-$B$51)))))/(1-(1/(1+EXP(-$B$52*(2026-$B$51))))) -> 5.9620892 | O18: =O17+N18 -> 18.926508 | P18: =MAX($B$53,Inputs!$B$40*(1-Inputs!$B$41)^B18) -> 21.719423 | Q18: =N18*P18 -> 129.49313 | R18: =Inputs!$B$43+($B$55-Inputs!$B$43)*((1/(1+EXP(-$B$57*($A18-$B$56))))-(1/(1+EXP(-$B$57*(2026-$B$56)))))/(1-(1/(1+EXP(-$B$57*(2026-$B$56))))) -> 875.77192 | S18: =MAX($B$58,Inputs!$B$44*(1-Inputs!$B$45)^B18) -> 162.884 | T18: =R18*S18/1000 -> 142.64923 | U18: =U17*(1+$B$60*Inputs!$B$48^(B18-1)) -> 49.841816 | V18: =G18+I18+M18+Q18+T18+U18 -> 1432.6612 | W18: =G18*(Inputs!$B$33+($B$38-Inputs!$B$33)*C18)+I18*$B$43+M18*(Inputs!$B$38+($B$49-Inputs!$B$38)*C18)+Q18*(Inputs!$B$42+($B$54-Inputs!$B$42)*C18)+T18*(Inputs!$B$46+($B$59-Inputs!$B$46)*C18)+U18*$B$61-V18*Inputs!$B$49 -> 563.21018 | X18: =(W18-V18*(Inputs!$B$50+Inputs!$B$51))*(1-Inputs!$B$52) -> 331.75581 | Y18: =$B$62+($B$63-$B$62)*MIN(1,MAX(0,(A18-2027)/(Inputs!$B$26-2027))) -> 23.636364 | Z18: =Inputs!$B$11*(1+$B$64)^B18 -> 4.1515278 | AA18: =MIN(1,B18/Inputs!$B$25)*(W19*Y18+Inputs!$B$28)+(1-MIN(1,B18/Inputs!$B$25))*Inputs!$B$9*Inputs!$B$11 -> 15189.419 | AB18: =AA18/Z18 -> 3658.7541 | AC18: =Inputs!$B$53+($B$65-Inputs!$B$53)*((1/(1+EXP(-$B$67*($A18-$B$66))))-(1/(1+EXP(-$B$67*(2026-$B$66)))))/(1-(1/(1+EXP(-$B$67*(2026-$B$66))))) -> 2137.1067 | AD18: =AC18*(Inputs!$B$54+($B$68-Inputs!$B$54)*C18) -> 961.69802 | AE18: =Inputs!$B$13*(1+$B$69)^B18 -> 15.748539 | AF18: =MIN(1,B18/Inputs!$B$25)*(AD19*Y18)+(1-MIN(1,B18/Inputs!$B$25))*Inputs!$B$12*Inputs!$B$13 -> 23028.41 | AG18: =AF18/AE18 -> 1462.2569 | AH18: =IF(AND(Inputs!$B$19="Yes",A18>=$B$5),1,0) -> 1 | AI18: =(AA18+AF18)*(1+IF(AH18=1,$B$70*MIN(1,(A18-$B$5+1)/3),0)) -> 42039.612 | AJ18: =AE18+Z18*$B$4 -> 25.444142 | AK18: =IF(AH18=1,Z18*$B$4/AJ18,1) -> 0.38105442 | AL18: =IF(AH18=1,$B$4*AI18/AJ18,AB18) -> 3858.6711 | AM18: =AL18*Holdings!$D$15 -> 1421843.1 | AN18: =AM18/Inputs!$B$14 -> 1074792.6 | AO18: =AN18/(1+Inputs!$B$17)^B18 -> 839626.25 | AP18: =AL18/Inputs!$B$9 -> 10.289789
